<sdf version='1.7'>
  <model name='s500_uam'>
    <link name='base_link'>
      <inertial>
        <pose>0 0 0 0 -0 0</pose>
        <mass>1.772</mass>
        <inertia>
          <ixx>0.0165</ixx>
          <ixy>0</ixy>
          <ixz>0</ixz>
          <iyy>0.0186</iyy>
          <iyz>0</iyz>
          <izz>0.025</izz>
        </inertia>
      </inertial>
      <collision name='base_link_collision'>
        <pose>0 0 0 0 -0 0</pose>
        <geometry>
          <mesh>
            <scale>1 1 1</scale>
            <uri>model://s500_quadrotor/meshes/base_link.STL</uri>
          </mesh>
        </geometry>
      </collision>
      <visual name='base_link_visual'>
        <pose>0 0 0 0 -0 0</pose>
        <geometry>
          <mesh>
            <scale>1 1 1</scale>
            <uri>model://s500_quadrotor/meshes/base_link.STL</uri>
          </mesh>
        </geometry>
      </visual>
    </link>
    <joint name='joint_1' type='revolute'>
      <pose relative_to='base_link'>0.0007 0 -0.07275 0 -0 0</pose>
      <parent>base_link</parent>
      <child>link_1</child>
      <axis>
        <xyz>0 1 0</xyz>
        <limit>
          <lower>-1e+16</lower>
          <upper>1e+16</upper>
        </limit>
        <dynamics>
          <spring_reference>0</spring_reference>
          <spring_stiffness>0</spring_stiffness>
        </dynamics>
      </axis>
    </joint>
    <link name='link_1'>
      <pose relative_to='joint_1'>0 0 0 0 -0 0</pose>
      <inertial>
        <pose>-0 -0.000196 -0.076809 0 -0 0</pose>
        <mass>0.056776</mass>
        <inertia>
          <ixx>1.5689e-05</ixx>
          <ixy>-1.0155e-16</ixy>
          <ixz>-5.2428e-15</ixz>
          <iyy>1.3617e-05</iyy>
          <iyz>-1.6017e-09</iyz>
          <izz>8.7857e-06</izz>
        </inertia>
      </inertial>
      <collision name='link_1_collision'>
        <pose>0 0 0 0 -0 0</pose>
        <geometry>
          <mesh>
            <scale>1 1 1</scale>
            <uri>model://s500_uam/meshes/link_1.STL</uri>
          </mesh>
        </geometry>
      </collision>
      <visual name='link_1_visual'>
        <pose>0 0 0 0 -0 0</pose>
        <geometry>
          <mesh>
            <scale>1 1 1</scale>
            <uri>model://s500_uam/meshes/link_1.STL</uri>
          </mesh>
        </geometry>
      </visual>
    </link>
    <joint name='joint_2' type='revolute'>
      <pose relative_to='link_1'>0 0 -0.09925 0 0.2936 0</pose>
      <parent>link_1</parent>
      <child>link_2</child>
      <axis>
        <xyz>0 1 0</xyz>
        <limit>
          <lower>-1e+16</lower>
          <upper>1e+16</upper>
        </limit>
        <dynamics>
          <spring_reference>0</spring_reference>
          <spring_stiffness>0</spring_stiffness>
        </dynamics>
      </axis>
    </joint>
    <link name='link_2'>
      <pose relative_to='joint_2'>0 0 0 0 -0 0</pose>
      <inertial>
        <pose>0.000575 0.000247 -0.072261 0 -0 0</pose>
        <mass>0.065663</mass>
        <inertia>
          <ixx>1.3006e-05</ixx>
          <ixy>2.5553e-07</ixy>
          <ixz>4.4082e-09</ixz>
          <iyy>1.4985e-05</iyy>
          <iyz>-6.0777e-07</iyz>
          <izz>1.6054e-05</izz>
        </inertia>
      </inertial>
      <collision name='link_2_collision'>
        <pose>0 0 0 0 -0 0</pose>
        <geometry>
          <mesh>
            <scale>1 1 1</scale>
            <uri>model://s500_uam/meshes/link_2.STL</uri>
          </mesh>
        </geometry>
      </collision>
      <visual name='link_2_visual'>
        <pose>0 0 0 0 -0 0</pose>
        <geometry>
          <mesh>
            <scale>1 1 1</scale>
            <uri>model://s500_uam/meshes/link_2.STL</uri>
          </mesh>
        </geometry>
      </visual>
    </link>
    <joint name='joint_3' type='revolute'>
      <pose relative_to='link_2'>-0.011 0 -0.08225 -0 0.23432 -3.14159</pose>
      <parent>link_2</parent>
      <child>link_3</child>
      <axis>
        <xyz>0 1 0</xyz>
        <limit>
          <lower>-1e+16</lower>
          <upper>1e+16</upper>
        </limit>
        <dynamics>
          <spring_reference>0</spring_reference>
          <spring_stiffness>0</spring_stiffness>
        </dynamics>
      </axis>
    </joint>
    <link name='link_3'>
      <pose relative_to='joint_3'>0 0 0 0 -0 0</pose>
      <inertial>
        <pose>0.025274 0.000991 -0.041284 0 -0 0</pose>
        <mass>0.012158</mass>
        <inertia>
          <ixx>1.0667e-05</ixx>
          <ixy>-2.5213e-09</ixy>
          <ixz>3.6553e-06</ixz>
          <iyy>1.2675e-05</iyy>
          <iyz>4.2721e-09</iyz>
          <izz>2.4775e-06</izz>
        </inertia>
      </inertial>
      <collision name='link_3_collision'>
        <pose>0 0 0 0 -0 0</pose>
        <geometry>
          <mesh>
            <scale>1 1 1</scale>
            <uri>model://s500_uam/meshes/link_3.STL</uri>
          </mesh>
        </geometry>
      </collision>
      <visual name='link_3_visual'>
        <pose>0 0 0 0 -0 0</pose>
        <geometry>
          <mesh>
            <scale>1 1 1</scale>
            <uri>model://s500_uam/meshes/link_3.STL</uri>
          </mesh>
        </geometry>
      </visual>
    </link>
    <joint name='joint_4' type='revolute'>
      <pose relative_to='link_2'>0.011 0 -0.08225 0 0.26237 0</pose>
      <parent>link_2</parent>
      <child>link_4</child>
      <axis>
        <xyz>0 1 0</xyz>
        <limit>
          <lower>-1e+16</lower>
          <upper>1e+16</upper>
        </limit>
        <dynamics>
          <spring_reference>0</spring_reference>
          <spring_stiffness>0</spring_stiffness>
        </dynamics>
      </axis>
    </joint>
    <link name='link_4'>
      <pose relative_to='joint_4'>0 0 0 0 -0 0</pose>
      <inertial>
        <pose>0.024422 -0.000991 -0.039818 0 -0 0</pose>
        <mass>0.012587</mass>
        <inertia>
          <ixx>1.1294e-05</ixx>
          <ixy>2.4212e-09</ixy>
          <ixz>4.0228e-06</ixz>
          <iyy>1.352e-05</iyy>
          <iyz>-4.1022e-09</iyz>
          <izz>2.6966e-06</izz>
        </inertia>
      </inertial>
      <collision name='link_4_collision'>
        <pose>0 0 0 0 -0 0</pose>
        <geometry>
          <mesh>
            <scale>1 1 1</scale>
            <uri>model://s500_uam/meshes/link_4.STL</uri>
          </mesh>
        </geometry>
      </collision>
      <visual name='link_4_visual'>
        <pose>0 0 0 0 -0 0</pose>
        <geometry>
          <mesh>
            <scale>1 1 1</scale>
            <uri>model://s500_uam/meshes/link_4.STL</uri>
          </mesh>
        </geometry>
      </visual>
    </link>
    <joint name='rotor_joint_1' type='revolute'>
      <pose relative_to='base_link'>0.171 0.171 0.045 0 -0 0</pose>
      <parent>base_link</parent>
      <child>rotor_1</child>
      <axis>
        <xyz>0 1 0</xyz>
        <limit>
          <lower>-1e+16</lower>
          <upper>1e+16</upper>
        </limit>
        <dynamics>
          <spring_reference>0</spring_reference>
          <spring_stiffness>0</spring_stiffness>
        </dynamics>
      </axis>
    </joint>
    <link name='rotor_1'>
      <pose relative_to='rotor_joint_1'>0 0 0 0 -0 0</pose>
      <inertial>
        <pose>0 0.025041 -1.5e-05 0 -0 0</pose>
        <mass>0.010198</mass>
        <inertia>
          <ixx>3.3719e-05</ixx>
          <ixy>7.4123e-13</ixy>
          <ixz>-4.3241e-07</ixz>
          <iyy>3.3918e-05</iyy>
          <iyz>-3.8834e-11</iyz>
          <izz>2.8343e-07</izz>
        </inertia>
      </inertial>
      <collision name='rotor_1_collision'>
        <pose>0 0 0 0 -0 0</pose>
        <geometry>
          <mesh>
            <scale>1 1 1</scale>
            <uri>model://s500_quadrotor/meshes/rotor_1.STL</uri>
          </mesh>
        </geometry>
      </collision>
      <visual name='rotor_1_visual'>
        <pose>0 0 0 0 -0 0</pose>
        <geometry>
          <mesh>
            <scale>1 1 1</scale>
            <uri>model://s500_quadrotor/meshes/iris_prop_ccw.dae</uri>
          </mesh>
        </geometry>
      </visual>
    </link>
    <joint name='rotor_joint_2' type='revolute'>
      <pose relative_to='base_link'>-0.171 0.171 0.045 0 -0 0</pose>
      <parent>base_link</parent>
      <child>rotor_2</child>
      <axis>
        <xyz>0 1 0</xyz>
        <limit>
          <lower>-1e+16</lower>
          <upper>1e+16</upper>
        </limit>
        <dynamics>
          <spring_reference>0</spring_reference>
          <spring_stiffness>0</spring_stiffness>
        </dynamics>
      </axis>
    </joint>
    <link name='rotor_2'>
      <pose relative_to='rotor_joint_2'>0 0 0 0 -0 0</pose>
      <inertial>
        <pose>0 0.027195 -1.4e-05 0 -0 0</pose>
        <mass>0.010198</mass>
        <inertia>
          <ixx>3.3719e-05</ixx>
          <ixy>-8.3558e-13</ixy>
          <ixz>-4.3246e-07</ixz>
          <iyy>3.3919e-05</iyy>
          <iyz>-4.2468e-11</iyz>
          <izz>2.8344e-07</izz>
        </inertia>
      </inertial>
      <collision name='rotor_2_collision'>
        <pose>0 0 0 0 -0 0</pose>
        <geometry>
          <mesh>
            <scale>1 1 1</scale>
            <uri>model://s500_quadrotor/meshes/rotor_2.STL</uri>
          </mesh>
        </geometry>
      </collision>
      <visual name='rotor_2_visual'>
        <pose>0 0 0 0 -0 0</pose>
        <geometry>
          <mesh>
            <scale>1 1 1</scale>
            <uri>model://s500_quadrotor/meshes/iris_prop_ccw.dae</uri>
          </mesh>
        </geometry>
      </visual>
    </link>
    <joint name='rotor_joint_3' type='revolute'>
      <pose relative_to='base_link'>-0.171 -0.171 0.045 0 -0 0</pose>
      <parent>base_link</parent>
      <child>rotor_3</child>
      <axis>
        <xyz>0 1 0</xyz>
        <limit>
          <lower>-1e+16</lower>
          <upper>1e+16</upper>
        </limit>
        <dynamics>
          <spring_reference>0</spring_reference>
          <spring_stiffness>0</spring_stiffness>
        </dynamics>
      </axis>
    </joint>
    <link name='rotor_3'>
      <pose relative_to='rotor_joint_3'>0 0 0 0 -0 0</pose>
      <inertial>
        <pose>0 0.011499 -1.4e-05 0 -0 0</pose>
        <mass>0.010198</mass>
        <inertia>
          <ixx>3.3719e-05</ixx>
          <ixy>1.6825e-12</ixy>
          <ixz>-4.3246e-07</ixz>
          <iyy>3.3919e-05</iyy>
          <iyz>-5.4463e-11</iyz>
          <izz>2.8343e-07</izz>
        </inertia>
      </inertial>
      <collision name='rotor_3_collision'>
        <pose>0 0 0 0 -0 0</pose>
        <geometry>
          <mesh>
            <scale>1 1 1</scale>
            <uri>model://s500_quadrotor/meshes/rotor_3.STL</uri>
          </mesh>
        </geometry>
      </collision>
      <visual name='rotor_3_visual'>
        <pose>0 0 0 0 -0 0</pose>
        <geometry>
          <mesh>
            <scale>1 1 1</scale>
            <uri>model://s500_quadrotor/meshes/iris_prop_cw.dae</uri>
          </mesh>
        </geometry>
      </visual>
    </link>
    <joint name='rotor_joint_4' type='revolute'>
      <pose relative_to='base_link'>0.1701 -0.1701 0.0603 0 -0 0</pose>
      <parent>base_link</parent>
      <child>rotor_4</child>
      <axis>
        <xyz>0 1 0</xyz>
        <limit>
          <lower>-1e+16</lower>
          <upper>1e+16</upper>
        </limit>
        <dynamics>
          <spring_reference>0</spring_reference>
          <spring_stiffness>0</spring_stiffness>
        </dynamics>
      </axis>
    </joint>
    <link name='rotor_4'>
      <pose relative_to='rotor_joint_4'>0 0 0 0 -0 0</pose>
      <inertial>
        <pose>0 0.009346 -1.4e-05 0 -0 0</pose>
        <mass>0.010198</mass>
        <inertia>
          <ixx>3.3719e-05</ixx>
          <ixy>1.1737e-12</ixy>
          <ixz>-4.3243e-07</ixz>
          <iyy>3.3918e-05</iyy>
          <iyz>-4.6991e-11</iyz>
          <izz>2.8343e-07</izz>
        </inertia>
      </inertial>
      <collision name='rotor_4_collision'>
        <pose>0 0 0 0 -0 0</pose>
        <geometry>
          <mesh>
            <scale>1 1 1</scale>
            <uri>model://s500_quadrotor/meshes/rotor_4.STL</uri>
          </mesh>
        </geometry>
      </collision>
      <visual name='rotor_4_visual'>
        <pose>0 0 0 0 -0 0</pose>
        <geometry>
          <mesh>
            <scale>1 1 1</scale>
            <uri>model://s500_quadrotor/meshes/iris_prop_cw.dae</uri>
          </mesh>
        </geometry>
      </visual>
    </link>
  </model>
</sdf>
