<?xml version="1.0" encoding="utf-8"?>
<!-- This URDF was automatically created by SolidWorks to URDF Exporter! Originally created by Stephen Brawner (brawner@gmail.com) 
     Commit Version: 1.6.0-4-g7f85cfe  Build Version: 1.6.7995.38578
     For more information, please see http://wiki.ros.org/sw_urdf_exporter -->
<robot name="s500_uam">
  <link name="base_link">
    <inertial>
      <origin
        xyz="0 0 0"
        rpy="0 0 0" />
      <mass
        value="1.772" />
      <inertia
        ixx="0.0165"
        ixy="0.0"
        ixz="0.0"
        iyy="0.0186"
        iyz="0.0"
        izz="0.0250" />
    </inertial>
    <visual>
      <origin
        xyz="0 0 0"
        rpy="0 0 0" />
      <geometry>
        <mesh
          filename="package://example-robot-data/robots/s500_description/s500_uam/meshes/base_link.dae" />
      </geometry>
      <material
        name="">
        <color
          rgba="0.752941176470588 0.752941176470588 0.752941176470588 1" />
      </material>
    </visual>
    <collision>
      <origin
        xyz="0 0 0"
        rpy="0 0 0" />
      <geometry>
        <mesh
          filename="package://example-robot-data/robots/s500_description/s500_uam/meshes/base_link.dae" />
      </geometry>
    </collision>
  </link>
  <link name="rotor_1">
    <inertial>
      <origin
        xyz="0 0 0"
        rpy="0 0 0" />
      <mass
        value="0.010198" />
      <inertia
        ixx="3.3719E-05"
        ixy="7.4123E-13"
        ixz="-4.3241E-07"
        iyy="3.3918E-05"
        iyz="-3.8834E-11"
        izz="2.8343E-07" />
    </inertial>
    <visual>
      <origin
        xyz="0 0 0"
        rpy="0 0 0" />
      <geometry>
        <mesh
          filename="package://example-robot-data/robots/s500_description/s500_uam/meshes/iris_prop_ccw.dae" />
      </geometry>
      <material
        name="">
        <color
          rgba="0.79216 0.81961 0.93333 1" />
      </material>
    </visual>
    <collision>
      <origin
        xyz="0 0 0"
        rpy="0 0 0" />
      <geometry>
        <mesh
          filename="package://example-robot-data/robots/s500_description/s500_uam/meshes/iris_prop_ccw.dae" />
      </geometry>
    </collision>
  </link>
  <joint name="rotor_joint_1" type="fixed">
    <origin
      xyz="0.171 0.171 0.07"
      rpy="0 0 0" />
    <parent
      link="base_link" />
    <child
      link="rotor_1" />
    <axis
      xyz="0 1 0" />
  </joint>
  <link name="rotor_2">
    <inertial>
      <origin
        xyz="0 0 0"
        rpy="0 0 0" />
      <mass
        value="0.010198" />
      <inertia
        ixx="3.3719E-05"
        ixy="-8.3558E-13"
        ixz="-4.3246E-07"
        iyy="3.3919E-05"
        iyz="-4.2468E-11"
        izz="2.8344E-07" />
    </inertial>
    <visual>
      <origin
        xyz="0 0 0"
        rpy="0 0 0" />
      <geometry>
        <mesh
          filename="package://example-robot-data/robots/s500_description/s500_uam/meshes/iris_prop_ccw.dae" />
      </geometry>
      <material
        name="">
        <color
          rgba="0.79216 0.81961 0.93333 1" />
      </material>
    </visual>
    <collision>
      <origin
        xyz="0 0 0"
        rpy="0 0 0" />
      <geometry>
        <mesh
          filename="package://example-robot-data/robots/s500_description/s500_uam/meshes/iris_prop_ccw.dae" />
      </geometry>
    </collision>
  </link>
  <joint name="rotor_joint_2" type="fixed">
    <origin
      xyz="-0.171 0.171 0.07"
      rpy="0 0 0" />
    <parent
      link="base_link" />
    <child
      link="rotor_2" />
    <axis
      xyz="0 1 0" />
  </joint>
  <link name="rotor_3">
    <inertial>
      <origin
        xyz="0 0 0"
        rpy="0 0 0" />
      <mass
        value="0.010198" />
      <inertia
        ixx="3.3719E-05"
        ixy="1.6825E-12"
        ixz="-4.3246E-07"
        iyy="3.3919E-05"
        iyz="-5.4463E-11"
        izz="2.8343E-07" />
    </inertial>
    <visual>
      <origin
        xyz="0 0 0"
        rpy="0 0 0" />
      <geometry>
        <mesh
          filename="package://example-robot-data/robots/s500_description/s500_uam/meshes/iris_prop_cw.dae" />
      </geometry>
      <material
        name="">
        <color
          rgba="0.79216 0.81961 0.93333 1" />
      </material>
    </visual>
    <collision>
      <origin
        xyz="0 0 0"
        rpy="0 0 0" />
      <geometry>
        <mesh
          filename="package://example-robot-data/robots/s500_description/s500_uam/meshes/iris_prop_cw.dae" />
      </geometry>
    </collision>
  </link>
  <joint name="rotor_joint_3" type="fixed">
    <origin
      xyz="-0.171 -0.171 0.07"
      rpy="0 0 0" />
    <parent
      link="base_link" />
    <child
      link="rotor_3" />
    <axis
      xyz="0 1 0" />
  </joint>
  <link name="rotor_4">
    <inertial>
      <origin
        xyz="0 0 0"
        rpy="0 0 0" />
      <mass
        value="0.010198" />
      <inertia
        ixx="3.3719E-05"
        ixy="1.1737E-12"
        ixz="-4.3243E-07"
        iyy="3.3918E-05"
        iyz="-4.6991E-11"
        izz="2.8343E-07" />
    </inertial>
    <visual>
      <origin
        xyz="0 0 0"
        rpy="0 0 0" />
      <geometry>
        <mesh
          filename="package://example-robot-data/robots/s500_description/s500_uam/meshes/iris_prop_cw.dae" />
      </geometry>
      <material
        name="">
        <color
          rgba="0.79216 0.81961 0.93333 1" />
      </material>
    </visual>
    <collision>
      <origin
        xyz="0 0 0"
        rpy="0 0 0" />
      <geometry>
        <mesh
          filename="package://example-robot-data/robots/s500_description/s500_uam/meshes/iris_prop_cw.dae" />
      </geometry>
    </collision>
  </link>
  <joint name="rotor_joint_4" type="fixed">
    <origin
      xyz="0.1701 -0.1701 0.07"
      rpy="0 0 0" />
    <parent
      link="base_link" />
    <child
      link="rotor_4" />
    <axis
      xyz="0 1 0" />
  </joint>
  <link name="link_1">
    <inertial>
      <origin
        xyz="-5.7463E-12 -0.00019643 -0.076809"
        rpy="0 0 0" />
      <mass
        value="0.056776" />
      <inertia
        ixx="1.5689E-05"
        ixy="-1.0155E-16"
        ixz="-5.2428E-15"
        iyy="1.3617E-05"
        iyz="-1.6017E-09"
        izz="8.7857E-06" />
    </inertial>
    <visual>
      <origin
        xyz="0 0 0"
        rpy="0 0 0" />
      <geometry>
        <mesh
          filename="package://example-robot-data/robots/s500_description/s500_uam/meshes/link_1.STL" />
      </geometry>
      <material
        name="">
        <color
          rgba="1 1 1 1" />
      </material>
    </visual>
    <collision>
      <origin
        xyz="0 0 0"
        rpy="0 0 0" />
      <geometry>
        <mesh
          filename="package://example-robot-data/robots/s500_description/s500_uam/meshes/link_1.STL" />
      </geometry>
    </collision>
  </link>
  <joint name="joint_1" type="revolute">
    <origin
      xyz="0.0007 0 -0.07275"
      rpy="0 0 0" />
    <parent
      link="base_link" />
    <child
      link="link_1" />
    <axis xyz="0 1 0" />
    <limit effort="1" lower="-1.5" upper="1.5" velocity="3"/>
    <dynamics damping="0.1" friction="0.1"/>
  </joint>
  <link name="link_2">
    <inertial>
      <origin
        xyz="0.00057539 0.00024651 -0.072261"
        rpy="0 0 0" />
      <mass
        value="0.065663" />
      <inertia
        ixx="1.3006E-05"
        ixy="2.5553E-07"
        ixz="4.4082E-09"
        iyy="1.4985E-05"
        iyz="-6.0777E-07"
        izz="1.6054E-05" />
    </inertial>
    <visual>
      <origin
        xyz="0 0 0"
        rpy="0 0 0" />
      <geometry>
        <mesh
          filename="package://example-robot-data/robots/s500_description/s500_uam/meshes/link_2.STL" />
      </geometry>
      <material
        name="">
        <color
          rgba="1 1 1 1" />
      </material>
    </visual>
    <collision>
      <origin
        xyz="0 0 0"
        rpy="0 0 0" />
      <geometry>
        <mesh
          filename="package://example-robot-data/robots/s500_description/s500_uam/meshes/link_2.STL" />
      </geometry>
    </collision>
  </link>
  <joint name="joint_2" type="revolute">
    <origin
      xyz="0 0 -0.09925"
      rpy="0 0 0" />
    <parent
      link="link_1" />
    <child
      link="link_2" />
    <axis xyz="0 1 0" />
    <limit effort="1" lower="-1.5" upper="1.5" velocity="3"/>
    <dynamics damping="0.1" friction="0.1"/>
  </joint>
  <link name="link_3">
    <inertial>
      <origin
        xyz="0.025274 0.000991 -0.041284"
        rpy="0 0 0" />
      <mass
        value="0.012158" />
      <inertia
        ixx="1.0667E-05"
        ixy="-2.5213E-09"
        ixz="3.6553E-06"
        iyy="1.2675E-05"
        iyz="4.2721E-09"
        izz="2.4775E-06" />
    </inertial>
    <visual>
      <origin
        xyz="0 0 0"
        rpy="0 0 0" />
      <geometry>
        <mesh
          filename="package://example-robot-data/robots/s500_description/s500_uam/meshes/link_3.STL" />
      </geometry>
      <material
        name="">
        <color
          rgba="0.92157 0.92157 0.92157 1" />
      </material>
    </visual>
    <collision>
      <origin
        xyz="0 0 0"
        rpy="0 0 0" />
      <geometry>
        <mesh
          filename="package://example-robot-data/robots/s500_description/s500_uam/meshes/link_3.STL" />
      </geometry>
    </collision>
  </link>
  <joint name="joint_3" type="fixed">
    <origin
      xyz="-0.011 0 -0.08225"
      rpy="0 0.23432 3.1416" />
    <parent
      link="link_2" />
    <child
      link="link_3" />
    <axis
      xyz="0 1 0" />
    <limit
      lower="-1.57"
      upper="0"
      effort="10"
      velocity="1" />
  </joint>
  <link name="link_4">
    <inertial>
      <origin
        xyz="0.024422 -0.0009913 -0.039818"
        rpy="0 0 0" />
      <mass
        value="0.012587" />
      <inertia
        ixx="1.1294E-05"
        ixy="2.4212E-09"
        ixz="4.0228E-06"
        iyy="1.352E-05"
        iyz="-4.1022E-09"
        izz="2.6966E-06" />
    </inertial>
    <visual>
      <origin
        xyz="0 0 0"
        rpy="0 0 0" />
      <geometry>
        <mesh
          filename="package://example-robot-data/robots/s500_description/s500_uam/meshes/link_4.STL" />
      </geometry>
      <material
        name="">
        <color
          rgba="0.92157 0.92157 0.92157 1" />
      </material>
    </visual>
    <collision>
      <origin
        xyz="0 0 0"
        rpy="0 0 0" />
      <geometry>
        <mesh
          filename="package://example-robot-data/robots/s500_description/s500_uam/meshes/link_4.STL" />
      </geometry>
    </collision>
  </link>
  <joint name="joint_4" type="fixed">
    <origin
      xyz="0.011 0 -0.08225"
      rpy="0 0.26237 0" />
    <parent
      link="link_2" />
    <child
      link="link_4" />
    <axis
      xyz="0 1 0" />
    <limit
      lower="0"
      upper="1.57"
      effort="10"
      velocity="1" />
  </joint>

  <link name="gripper_link">
    <visual>
        <origin xyz="0 0 0" rpy="0 0 0" />
        <geometry>
            <!-- 使用一个小的box或sphere作为可视化 -->
            <box size="0.01 0.01 0.01" />  <!-- 或者使用 <sphere radius="0.005" /> -->
        </geometry>
        <material name="">
            <color rgba="1 0 0 0.5" />  <!-- 红色，半透明 -->
        </material>
    </visual>
    <!-- 不需要collision和inertial属性，因为这是虚拟link -->
  </link>
  <joint name="gripper_joint" type="fixed">
    <origin xyz="0 0 -0.14" rpy="0 0 0" />  <!-- 调整xyz和rpy以匹配爪子位置 -->
    <parent link="link_2" />
    <child link="gripper_link" />
  </joint>

</robot>