<?xml version="1.0" encoding="utf-8"?>
<robot name="hexacopter370_flying_arm_5">
  
  <link name="hexacopter370__base_link">
    <inertial>
      <mass value="1.9828" />
      <origin xyz="0 0 0" />
      <inertia ixx="0.0134943" ixy="-9.6E-06" ixz="2.82E-05" iyy="0.0141622" iyz="-7.9E-06" izz="0.0237319" />
    </inertial>
    <visual>
      <origin rpy="0 0 0" xyz="0 0 0" />
      <geometry>
        <mesh filename="package://example-robot-data/robots/hexacopter370_description/meshes/hexacopter370.dae" scale="1 1 1" />
      </geometry>
      <material name="">
        <color rgba="0.8471 0.6078 0.3412 1" />
      </material>
    </visual>
    <collision>
      <origin rpy="0 0 0" xyz="0 0 0" />
      <geometry>
        <box size="0.4 0.4 0.2"/>
      </geometry>
    </collision>
  </link>

  <joint name="hexacopter370__rotor_0_joint" type="fixed">
    <origin rpy="0 0 0" xyz="0.16021469970004 0.0925 0.05" />
    <axis xyz="0 0 1" />
    <parent link="hexacopter370__base_link" />
    <child link="hexacopter370__rotor_0" />
  </joint>

  <link name="hexacopter370__rotor_0">
    <inertial>
      <mass value="0.005" />
      <inertia ixx="9.7499961e-07" ixy="0.0" ixz="0.0" iyy="3.296752847965001e-05" iyz="0.0" izz="3.386752811965e-05" />
    </inertial>
    <visual>
      <geometry>
        <mesh filename="package://example-robot-data/robots/hexacopter370_description/meshes/propeller_ccw.dae" scale="0.0889 0.0889 0.0889" />
      </geometry>
      <material name="">
        <color rgba="0.3020 0.2784 0.2706 1" />
      </material>
    </visual>
    <collision>
      <geometry>
        <cylinder length="0.005" radius="0.0889" />
      </geometry>
    </collision>
  </link>

  <joint name="hexacopter370__rotor_1_joint" type="fixed">
    <origin rpy="0 0 0" xyz="0 0.185 0.05" />
    <axis xyz="0 0 1" />
    <parent link="hexacopter370__base_link" />
    <child link="hexacopter370__rotor_1" />
  </joint>
  <link name="hexacopter370__rotor_1">
    <inertial>
      <mass value="0.005" />
      <inertia ixx="9.7499961e-07" ixy="0.0" ixz="0.0" iyy="3.296752847965001e-05" iyz="0.0" izz="3.386752811965e-05" />
    </inertial>
    <visual>
      <geometry>
        <mesh filename="package://example-robot-data/robots/hexacopter370_description/meshes/propeller_cw.dae" scale="0.0889 0.0889 0.0889" />
      </geometry>
      <material name="">
        <color rgba="0.8941 0.3137 0.1882 1" />
      </material>
    </visual>
    <collision>
      <geometry>
        <cylinder length="0.005" radius="0.0889" />
      </geometry>
    </collision>
  </link>
  <joint name="hexacopter370__rotor_2_joint" type="fixed">
    <origin rpy="0 0 0" xyz="-0.16021469970004 0.0925 0.05" />
    <axis xyz="0 0 1" />
    <parent link="hexacopter370__base_link" />
    <child link="hexacopter370__rotor_2" />
  </joint>
  <link name="hexacopter370__rotor_2">
    <inertial>
      <mass value="0.005" />
      <inertia ixx="9.7499961e-07" ixy="0.0" ixz="0.0" iyy="3.296752847965001e-05" iyz="0.0" izz="3.386752811965e-05" />
    </inertial>
    <visual>
      <geometry>
        <mesh filename="package://example-robot-data/robots/hexacopter370_description/meshes/propeller_ccw.dae" scale="0.0889 0.0889 0.0889" />
      </geometry>
      <material name="">
        <color rgba="0.8941 0.3137 0.1882 1" />
      </material>
    </visual>
    <collision>
      <geometry>
        <cylinder length="0.005" radius="0.0889" />
      </geometry>
    </collision>
  </link>
  <joint name="hexacopter370__rotor_3_joint" type="fixed">
    <origin rpy="0 0 0" xyz="-0.16021469970004 -0.0925 0.05" />
    <axis xyz="0 0 1" />
    <parent link="hexacopter370__base_link" />
    <child link="hexacopter370__rotor_3" />
  </joint>
  <link name="hexacopter370__rotor_3">
    <inertial>
      <mass value="0.005" />
      <inertia ixx="9.7499961e-07" ixy="0.0" ixz="0.0" iyy="3.296752847965001e-05" iyz="0.0" izz="3.386752811965e-05" />
    </inertial>
    <visual>
      <geometry>
        <mesh filename="package://example-robot-data/robots/hexacopter370_description/meshes/propeller_cw.dae" scale="0.0889 0.0889 0.0889" />
      </geometry>
      <material name="">
        <color rgba="0.8941 0.3137 0.1882 1" />
      </material>
    </visual>
    <collision>
      <geometry>
        <cylinder length="0.005" radius="0.0889" />
      </geometry>
    </collision>
  </link>
  <joint name="hexacopter370__rotor_4_joint" type="fixed">
    <origin rpy="0 0 0" xyz="0 -0.185 0.05" />
    <axis xyz="0 0 1" />
    <parent link="hexacopter370__base_link" />
    <child link="hexacopter370__rotor_4" />
  </joint>
  <link name="hexacopter370__rotor_4">
    <inertial>
      <mass value="0.005" />
      <inertia ixx="9.7499961e-07" ixy="0.0" ixz="0.0" iyy="3.296752847965001e-05" iyz="0.0" izz="3.386752811965e-05" />
    </inertial>
    <visual>
      <geometry>
        <mesh filename="package://example-robot-data/robots/hexacopter370_description/meshes/propeller_ccw.dae" scale="0.0889 0.0889 0.0889" />
      </geometry>
      <material name="">
        <color rgba="0.8941 0.3137 0.1882 1" />
      </material>
    </visual>
    <collision>
      <geometry>
        <cylinder length="0.005" radius="0.0889" />
      </geometry>
    </collision>
  </link>
  <joint name="hexacopter370__rotor_5_joint" type="fixed">
    <origin rpy="0 0 0" xyz="0.16021469970004 -0.0925 0.05" />
    <axis xyz="0 0 1" />
    <parent link="hexacopter370__base_link" />
    <child link="hexacopter370__rotor_5" />
  </joint>
  <link name="hexacopter370__rotor_5">
    <inertial>
      <mass value="0.005" />
      <inertia ixx="9.7499961e-07" ixy="0.0" ixz="0.0" iyy="3.296752847965001e-05" iyz="0.0" izz="3.386752811965e-05" />
    </inertial>
    <visual>
      <geometry>
        <mesh filename="package://example-robot-data/robots/hexacopter370_description/meshes/propeller_cw.dae" scale="0.0889 0.0889 0.0889" />
      </geometry>
      <material name="">
        <color rgba="0.3020 0.2784 0.2706 1" />
      </material>
    </visual>
    <collision>
      <geometry>
        <cylinder length="0.005" radius="0.0889" />
      </geometry>
    </collision>
  </link>

  <joint name="flying_arm_5__j_base_link" type="fixed">
    <origin rpy="0 0 0" xyz="0.0 0.0 -0.10" />
    <parent link="hexacopter370__base_link" />
    <child link="flying_arm_5__base_link" />
  </joint>
  <link name="flying_arm_5__base_link">
    <inertial>
      <origin rpy="0 0 0" xyz="5.4471E-05 0.00055544 0.0045971" />
      <mass value="0.27973" />
      <inertia ixx="0.00010284" ixy="5.704E-10" ixz="7.6592E-09" iyy="7.9509E-05" iyz="5.7105E-10" izz="9.2151E-05" />
    </inertial>
    <visual>
      <origin rpy="0 0 0" xyz="0 0 0" />
      <geometry>
        <mesh filename="package://example-robot-data/robots/flying_arm_5_description/meshes/base_link.dae" />
      </geometry>
      <material name="">
        <color rgba="0.8471 0.6078 0.3412 1" />
      </material>
    </visual>
  </link>

  <joint name="flying_arm_5__j_base_link_link_1" type="revolute">
    <origin rpy="1.5708 1.5708 0" xyz="0 0 0" />
    <parent link="flying_arm_5__base_link" />
    <child link="flying_arm_5__link_1" />
    <axis xyz="0 0 1" />
    <limit effort="1" lower="-1.6707963267948966" upper="1.6707963267948966" velocity="10000" />
    <dynamics damping="0.1" friction="0.1" />
  </joint>

  <link name="flying_arm_5__link_1">
    <inertial>
      <origin rpy="0 0 0" xyz="0.097289 5.2467E-05 -0.012147" />
      <mass value="0.12284" />
      <inertia ixx="2.3846E-05" ixy="-5.0883E-13" ixz="3.5276E-06" iyy="0.00021635" iyz="-1.2916E-12" izz="0.00023624" />
    </inertial>
    <visual>
      <origin rpy="0 0 0" xyz="0 0 0" />
      <geometry>
        <mesh filename="package://example-robot-data/robots/flying_arm_5_description/meshes/link_1.dae" />
      </geometry>
      <material name="">
        <color rgba="0.8314 0.8471 0.3412 1" />
      </material>
    </visual>
  </link>

  <link name="flying_arm_5__link_2">
    <inertial>
      <origin rpy="0 0 0" xyz="0.043238 2.4308E-05 -0.0087926"/>
      <mass value="0.11474"/>
      <inertia ixx="1.174E-05" ixy="1.3294E-09" ixz="-2.0499E-06" iyy="4.7747E-05" iyz="-1.6102E-08" izz="5.2344E-05"/>
    </inertial>
    <visual>
      <origin rpy="0 0 0" xyz="0 0 0"/>
      <geometry>
        <mesh filename="package://example-robot-data/robots/flying_arm_5_description/meshes/link_2.dae"/>
      </geometry>
      <material name="">
        <color rgba="0.5804 0.8471 0.3412 1"/>
      </material>
    </visual>
  </link>

  <joint name="flying_arm_5__j_link_1_link_2" type="revolute">
    <origin rpy="0 0 0" xyz="0.132 0 0"/>
    <parent link="flying_arm_5__link_1"/>
    <child link="flying_arm_5__link_2"/>
    <axis xyz="0 0 1"/>
    <limit effort="1" lower="-1.6707963267948966" upper="1.6707963267948966" velocity="10000"/>
    <dynamics damping="0.1" friction="0.1"/>
  </joint>

  <link name="flying_arm_5__link_3">
    <inertial>
      <origin rpy="0 0 0" xyz="0.00020827 -0.0031223 -0.011966"/>
      <mass value="0.068772"/>
      <inertia ixx="6.8293E-06" ixy="4.2309E-08" ixz="1.548E-09" iyy="7.2432E-06" iyz="1.6138E-08" izz="7.1043E-06"/>
    </inertial>
    <visual>
      <origin rpy="0 0 0" xyz="0 0 0"/>
      <geometry>
        <mesh filename="package://example-robot-data/robots/flying_arm_5_description/meshes/link_3.dae"/>
      </geometry>
      <material name="">
        <color rgba="0.3412 0.8471 0.3569 1"/>
      </material>
    </visual>
  </link>

  <joint name="flying_arm_5__j_link_2_link_3" type="revolute">
    <origin rpy="0 0 0" xyz="0.075 0 0"/>
    <parent link="flying_arm_5__link_2"/>
    <child link="flying_arm_5__link_3"/>
    <axis xyz="0 0 1"/>
    <limit effort="0.3" lower="-1.6707963267948966" upper="1.6707963267948966" velocity="10000"/>
    <dynamics damping="0.1" friction="0.1"/>
  </joint>

  <link name="flying_arm_5__link_4">
    <inertial>
      <origin rpy="0 0 0" xyz="0.026125 2.9724E-09 0.0016875"/>
      <mass value="0.05914"/>
      <inertia ixx="2.2712E-05" ixy="2.3256E-12" ixz="5.2509E-09" iyy="2.472E-05" iyz="3.3225E-09" izz="1.0444E-05"/>
    </inertial>
    <visual>
      <origin rpy="0 0 0" xyz="0 0 0"/>
      <geometry>
        <mesh filename="package://example-robot-data/robots/flying_arm_5_description/meshes/link_4.dae"/>
      </geometry>
      <material name="">
        <color rgba="0.3412 0.8471 0.6078 1"/>
      </material>
    </visual>
  </link>
  
  <joint name="flying_arm_5__j_link_3_link_4" type="revolute">
    <origin rpy="1.5708 0 0" xyz="0 0 -0.011925"/>
    <parent link="flying_arm_5__link_3"/>
    <child link="flying_arm_5__link_4"/>
    <axis xyz="0 0 1"/>
    <limit effort="0.3" lower="-1.6707963267948966" upper="1.6707963267948966" velocity="10000"/>
    <dynamics damping="0.1" friction="0.1"/>
  </joint>

  <link name="flying_arm_5__link_5">
    <inertial>
      <origin rpy="0 0 0" xyz="1.7347E-18 -1.0246E-17 0.025817"/>
      <mass value="0.021791"/>
      <inertia ixx="7.9107E-06" ixy="1.6653E-13" ixz="2.9904E-21" iyy="1.5446E-05" iyz="-1.1963E-21" izz="1.0818E-05"/>
    </inertial>
    <visual>
      <origin rpy="0 0 0" xyz="0 0 0"/>
      <geometry>
        <mesh filename="package://example-robot-data/robots/flying_arm_5_description/meshes/link_5.dae"/>
      </geometry>
      <material name="">
        <color rgba="0.3412 0.8314 0.8471 1"/>
      </material>
    </visual>
  </link>

  <joint name="flying_arm_5__j_link_4_link_5" type="revolute">
    <origin rpy="1.5708 0 1.5708" xyz="0.034 0 -0.00025"/>
    <parent link="flying_arm_5__link_4"/>
    <child link="flying_arm_5__link_5"/>
    <axis xyz="0 0 1"/>
    <limit effort="0.3" lower="-1.6707963267948966" upper="1.6707963267948966" velocity="10000"/>
  </joint>

</robot>