<?xml version="1.0" encoding="utf-8"?>
<robot name="hexacopter370_flying_arm_1">
  
  <link name="hexacopter370__base_link">
    <inertial>
      <mass value="1.9828" />
      <origin xyz="0 0 0" />
      <inertia ixx="0.0134943" ixy="-9.6E-06" ixz="2.82E-05" iyy="0.0141622" iyz="-7.9E-06" izz="0.0237319" />
    </inertial>
    <visual>
      <origin rpy="0 0 0" xyz="0 0 0" />
      <geometry>
        <mesh filename="package://example-robot-data/robots/hexacopter370_description/meshes/hexacopter370.dae" scale="1 1 1" />
      </geometry>
      <material name="">
        <color rgba="0.8471 0.6078 0.3412 1" />
      </material>
    </visual>
    <collision>
      <origin rpy="0 0 0" xyz="0 0 0" />
      <geometry>
        <box size="0.4 0.4 0.2"/>
      </geometry>
    </collision>
  </link>

  <joint name="flying_arm_3__j_base_link" type="fixed">
    <origin rpy="0 0 0" xyz="0.0 0.0 -0.10" />
    <parent link="hexacopter370__base_link" />
    <child link="flying_arm_3__base_link" />
  </joint>
  
  <link name="flying_arm_3__base_link">
    <inertial>
      <origin rpy="0 0 0" xyz="5.4471E-05 0.00055544 0.0045971" />
      <mass value="0.27973" />
      <inertia ixx="0.00010284" ixy="5.704E-10" ixz="7.6592E-09" iyy="7.9509E-05" iyz="5.7105E-10" izz="9.2151E-05" />
    </inertial>
    <visual>
      <origin rpy="0 0 0" xyz="0 0 0" />
      <geometry>
        <mesh filename="package://example-robot-data/robots/flying_arm_3_description/meshes/base_link.dae" />
      </geometry>
      <material name="">
        <color rgba="0.8471 0.6078 0.3412 1" />
      </material>
    </visual>
  </link>

  <joint name="flying_arm_3__j_base_link_link_1" type="revolute">
    <origin rpy="1.5708 1.5708 0" xyz="0 0 0" />
    <parent link="flying_arm_3__base_link" />
    <child link="flying_arm_3__link_1" />
    <axis xyz="0 0 1" />
    <limit effort="1" lower="-1.6707963267948966" upper="1.6707963267948966" velocity="10000" />
    <dynamics damping="0.1" friction="0.1" />
  </joint>

  <link name="flying_arm_3__link_1">
    <inertial>
      <origin rpy="0 0 0" xyz="0.097289 5.2467E-05 -0.012147" />
      <mass value="0.12284" />
      <inertia ixx="2.3846E-05" ixy="-5.0883E-13" ixz="3.5276E-06" iyy="0.00021635" iyz="-1.2916E-12" izz="0.00023624" />
    </inertial>
    <visual>
      <origin rpy="0 0 0" xyz="0 0 0" />
      <geometry>
        <mesh filename="package://example-robot-data/robots/flying_arm_3_description/meshes/link_1.dae" />
      </geometry>
      <material name="">
        <color rgba="0.8314 0.8471 0.3412 1" />
      </material>
    </visual>
  </link>

</robot>